Workbook

Sheet Read me
A1: Buna A1 curriculum: English speakers learning Amharic and Afaan Oromo
A3: What this is
A4: The plan and the words for the first CEFR level (A1). One English plan is shared by both courses, so the two courses teach the same things in the same order.
A5: Section 0: sounds and writing (Fidel for Amharic, Qubee for Afaan Oromo). Planned only; it needs its own lesson type in the app.
A6: Section 1 (A1.1): drafted in both languages by Claude on 2026-10-03. NOT yet checked by a native speaker.
A7: Section 2 (A1.2): English words and sentences only. The yellow cells are for native speakers to fill in.
A9: How to fill it in
A10: 1. Yellow cells are for you to fill in or correct. Leave the white cells (IDs, English) as they are, unless the English itself is wrong.
A11: 2. Amharic in Fidel; the romanization column helps learners and audio recorders. Afaan Oromo in standard Qubee spelling.
A12: 3. After checking a row, set its Status to Reviewed (or Needs change, with a comment). The Progress tab counts these.
A13: 4. 'Claude confidence' shows how sure the draft was: check Low and Medium rows first.
A14: 5. 'Word to blank' is the word the gap-fill exercise hides; it must appear exactly in the sentence.
... A23: S1-U06-L1 | coffee | ቡና | bunna | buna | High | High | Reviewed | Reviewed | Y | Y

Sheet Plan
A1: Lesson ID | B1: Section | C1: Skill # | D1: Skill | E1: Lesson # | F1: Lesson | G1: Can-do goal (CEFR) | H1: Grammar: Amharic | I1: Grammar: Afaan Oromo
A2: S0-U00-L1 | B2: Section 0 · Sounds & writing | C2: 0 | D2: Sounds & writing | E2: 1 | F2: Vowels & first letters | G2: Can read and pronounce the letters and sounds of the language. | H2: Fidel: 33 base letters × 7 vowel orders (ሀ ሁ ሂ ሃ ሄ ህ ሆ); ejectives ጥ ጭ ቅ ጵ ጽ; gemination is not written. | I2: Qubee (Latin letters): long vowels written double (aa, ee); double consonants (ll, nn); digraphs ch, dh, ny, ph, sh; ejectives c, q, x, ph; glottal stop '.
A3: S0-U00-L2 | B3: Section 0 · Sounds & writing | C3: 0 | D3: Sounds & writing | E3: 2 | F3: Special sounds | G3: Can read and pronounce the letters and sounds of the language. | H3: Fidel: 33 base letters × 7 vowel orders (ሀ ሁ ሂ ሃ ሄ ህ ሆ); ejectives ጥ ጭ ቅ ጵ ጽ; gemination is not written. | I3: Qubee (Latin letters): long vowels written double (aa, ee); double consonants (ll, nn); digraphs ch, dh, ny, ph, sh; ejectives c, q, x, ph; glottal stop '.
A4: S0-U00-L3 | B4: Section 0 · Sounds & writing | C4: 0 | D4: Sounds & writing | E4: 3 | F4: Reading first words | G4: Can read and pronounce the letters and sounds of the language. | H4: Fidel: 33 base letters × 7 vowel orders (ሀ ሁ ሂ ሃ ሄ ህ ሆ); ejectives ጥ ጭ ቅ ጵ ጽ; gemination is not written. | I4: Qubee (Latin letters): long vowels written double (aa, ee); double consonants (ll, nn); digraphs ch, dh, ny, ph, sh; ejectives c, q, x, ph; glottal stop '.
A5: S1-U01-L1 | B5: Section 1 · First conversations (A1.1) | C5: 1 | D5: Greetings | E5: 1 | F5: Hello & goodbye | G5: Can greet people, say goodbye and ask how someone is. | H5: Polite forms (ይሁኑ, አደሩ) avoid gender; informal forms differ for a man and a woman (ሁን / ሁኚ). | I5: Singular vs plural/polite: Akkam bulte? (one person) / Akkam bultan? (several, or polite).
A6: S1-U01-L2 | B6: Section 1 · First conversations (A1.1) | C6: 1 | D6: Greetings | E6: 2 | F6: How are you? | G6: Can greet people, say goodbye and ask how someone is. | H6: Polite forms (ይሁኑ, አደሩ) avoid gender; informal forms differ for a man and a woman (ሁን / ሁኚ). | I6: Singular vs plural/polite: Akkam bulte? (one person) / Akkam bultan? (several, or polite).
A7: S1-U01-L3 | B7: Section 1 · First conversations (A1.1) | C7: 1 | D7: Greetings | E7: 3 | F7: Thank you & sorry | G7: Can greet people, say goodbye and ask how someone is. | H7: Polite forms (ይሁኑ, አደሩ) avoid gender; informal forms differ for a man and a woman (ሁን / ሁኚ). | I7: Singular vs plural/polite: Akkam bulte? (one person) / Akkam bultan? (several, or polite).
A8: S1-U02-L1 | B8: Section 1 · First conversations (A1.1) | C8: 2 | D8: Introductions | E8: 1 | F8: My name is… | G8: Can say their name and where they are from, and ask others. | H8: Copula ነው / ነኝ ('is' / 'am') at the end; possessive suffix -e ('my'): ስም → ስሜ. | I8: Copula dha at the end; koo 'my', kee 'your'; subject ending -n: maqaa → maqaan.
A9: S1-U02-L2 | B9: Section 1 · First conversations (A1.1) | C9: 2 | D9: Introductions | E9: 2 | F9: Where are you from? | G9: Can say their name and where they are from, and ask others. | H9: Copula ነው / ነኝ ('is' / 'am') at the end; possessive suffix -e ('my'): ስም → ስሜ. | I9: Copula dha at the end; koo 'my', kee 'your'; subject ending -n: maqaa → maqaan.
A10: S1-U02-L3 | B10: Section 1 · First conversations (A1.1) | C10: 2 | D10: Introductions | E10: 3 | F10: Nice to meet you | G10: Can say their name and where they are from, and ask others. | H10: Copula ነው / ነኝ ('is' / 'am') at the end; possessive suffix -e ('my'): ስም → ስሜ. | I10: Copula dha at the end; koo 'my', kee 'your'; subject ending -n: maqaa → maqaan.
A11: S1-U03-L1 | B11: Section 1 · First conversations (A1.1) | C11: 3 | D11: People | E11: 1 | F11: I & you | G11: Can name people and say who someone is. | H11: Pronouns have gender in 'you' and 'he/she' (አንተ / አንቺ, እሱ / እሷ); copula agrees: ነኝ ነህ ነሽ ነው ናት. | I11: Pronouns ani, ati, inni, isheen, nuyi, isaan; 'you' has no gender.
A12: S1-U03-L2 | B12: Section 1 · First conversations (A1.1) | C12: 3 | D12: People | E12: 2 | F12: He, she, we, they | G12: Can name people and say who someone is. | H12: Pronouns have gender in 'you' and 'he/she' (አንተ / አንቺ, እሱ / እሷ); copula agrees: ነኝ ነህ ነሽ ነው ናት. | I12: Pronouns ani, ati, inni, isheen, nuyi, isaan; 'you' has no gender.
A13: S1-U03-L3 | B13: Section 1 · First conversations (A1.1) | C13: 3 | D13: People | E13: 3 | F13: Man, woman, teacher | G13: Can name people and say who someone is. | H13: Pronouns have gender in 'you' and 'he/she' (አንተ / አንቺ, እሱ / እሷ); copula agrees: ነኝ ነህ ነሽ ነው ናት. | I13: Pronouns ani, ati, inni, isheen, nuyi, isaan; 'you' has no gender.
... A70: S2-U22-L3 | B70: Section 2 · Daily life (A1.2) | C70: 22 | D70: Ethiopian culture | E70: 3 | F70: Celebrations | G70: Can talk about holidays and the coffee ceremony. | H70: Holiday greetings: እንኳን አደረሳችሁ. | I70: Holiday greetings: Baga geessan.

Sheet Words
A1: Word ID | B1: Lesson ID | C1: Section | D1: Skill | E1: Lesson | F1: English | G1: Amharic (Fidel) | H1: Amharic romanization | I1: Afaan Oromo | J1: Notes | K1: Claude confidence: Amharic | L1: Claude confidence: Oromo | M1: Status: Amharic | N1: Status: Oromo | O1: Audio: Amharic | P1: Audio: Oromo | Q1: Reviewer comments
A2: W001 | B2: S1-U01-L1 | C2: 1 | D2: Greetings | E2: Hello & goodbye | F2: hello | G2: ሰላም | H2: selam | I2: Akkam | J2: Oromo 'Akkam' is also 'how?'. | K2: High | L2: High | M2: Draft | N2: Draft | O2: N | P2: N
A3: W002 | B3: S1-U01-L1 | C3: 1 | D3: Greetings | E3: Hello & goodbye | F3: goodbye | G3: ደህና ይሁኑ | H3: dehna yihunu | I3: Nagaatti | J3: Amharic polite form; to a man ደህና ሁን, to a woman ደህና ሁኚ. | K3: High | L3: High | M3: Draft | N3: Draft | O3: N | P3: N
A4: W003 | B4: S1-U01-L1 | C4: 1 | D4: Greetings | E4: Hello & goodbye | F4: good morning | G4: እንደምን አደሩ | H4: indemin aderu | I4: Akkam bulte | J4: Literally 'how did you spend the night?'. Oromo plural/polite: Akkam bultan. | K4: High | L4: High | M4: Draft | N4: Draft | O4: N | P4: N
A5: W004 | B5: S1-U01-L1 | C5: 1 | D5: Greetings | E5: Hello & goodbye | F5: good night | G5: ደህና ይደሩ | H5: dehna yideru | I5: Halkan gaarii | K5: High | L5: Medium | M5: Draft | N5: Draft | O5: N | P5: N
A6: W005 | B6: S1-U01-L2 | C6: 1 | D6: Greetings | E6: How are you? | F6: How are you? | G6: እንዴት ነዎት? | H6: indet newot? | I6: Akkam jirta? | J6: Amharic polite; to a man እንዴት ነህ?, to a woman እንዴት ነሽ?. | K6: High | L6: High | M6: Draft | N6: Draft | O6: N | P6: N
A7: W006 | B7: S1-U01-L2 | C7: 1 | D7: Greetings | E7: How are you? | F7: fine / well | G7: ደህና | H7: dehna | I7: nagaa | K7: High | L7: Medium | M7: Draft | N7: Draft | O7: N | P7: N
A8: W007 | B8: S1-U01-L2 | C8: 1 | D8: Greetings | E8: How are you? | F8: I am fine | G8: ደህና ነኝ | H8: dehna negn | I8: Nagaa dha | J8: Oromo also: Fayyaa dha. | K8: High | L8: Medium | M8: Draft | N8: Draft | O8: N | P8: N
A9: W008 | B9: S1-U01-L2 | C9: 1 | D9: Greetings | E9: How are you? | F9: And you? | G9: እርስዎስ? | H9: irswos? | I9: Ati hoo? | K9: High | L9: Low | M9: Draft | N9: Draft | O9: N | P9: N
A10: W009 | B10: S1-U01-L3 | C10: 1 | D10: Greetings | E10: Thank you & sorry | F10: thank you | G10: አመሰግናለሁ | H10: ameseginalehu | I10: Galatoomi | K10: High | L10: High | M10: Draft | N10: Draft | O10: N | P10: N
A11: W010 | B11: S1-U01-L3 | C11: 1 | D11: Greetings | E11: Thank you & sorry | F11: please | G11: እባክዎ | H11: ibakwo | I11: Maaloo | J11: Amharic polite; to a man እባክህ, to a woman እባክሽ. | K11: High | L11: High | M11: Draft | N11: Draft | O11: N | P11: N
A12: W011 | B12: S1-U01-L3 | C12: 1 | D12: Greetings | E12: Thank you & sorry | F12: sorry | G12: ይቅርታ | H12: yiqirta | I12: Dhiifama | K12: High | L12: High | M12: Draft | N12: Draft | O12: N | P12: N
A13: W012 | B13: S1-U01-L3 | C13: 1 | D13: Greetings | E13: Thank you & sorry | F13: you're welcome | G13: ምንም አይደለም | H13: minim aydelem | I13: Homaa miti | J13: Literally 'it's nothing'. | K13: Medium | L13: Medium | M13: Draft | N13: Draft | O13: N | P13: N
A14: W013 | B14: S1-U02-L1 | C14: 1 | D14: Introductions | E14: My name is… | F14: name | G14: ስም | H14: sim | I14: maqaa | K14: High | L14: High | M14: Draft | N14: Draft | O14: N | P14: N
A15: W014 | B15: S1-U02-L1 | C15: 1 | D15: Introductions | E15: My name is… | F15: My name is … | G15: ስሜ … ነው | H15: sime … new | I15: Maqaan koo … dha | K15: High | L15: High | M15: Draft | N15: Draft | O15: N | P15: N
A16: W015 | B16: S1-U02-L1 | C16: 1 | D16: Introductions | E16: My name is… | F16: What is your name? | G16: ስምዎ ማን ነው? | H16: simwo man new? | I16: Maqaan kee eenyu? | J16: Amharic polite; informal ስምህ (man) / ስምሽ (woman). | K16: High | L16: High | M16: Draft | N16: Draft | O16: N | P16: N
A17: W016 | B17: S1-U02-L1 | C17: 1 | D17: Introductions | E17: My name is… | F17: who? | G17: ማን? | H17: man? | I17: eenyu? | K17: High | L17: High | M17: Draft | N17: Draft | O17: N | P17: N
A18: W017 | B18: S1-U02-L2 | C18: 1 | D18: Introductions | E18: Where are you from? | F18: country | G18: አገር | H18: ager | I18: biyya | K18: High | L18: High | M18: Draft | N18: Draft | O18: N | P18: N
A19: W018 | B19: S1-U02-L2 | C19: 1 | D19: Introductions | E19: Where are you from? | F19: Ethiopia | G19: ኢትዮጵያ | H19: Ityopya | I19: Itoophiyaa | K19: High | L19: High | M19: Draft | N19: Draft | O19: N | P19: N
A20: W019 | B20: S1-U02-L2 | C20: 1 | D20: Introductions | E20: Where are you from? | F20: Where are you from? | G20: ከየት ነዎት? | H20: keyet newot? | I20: Eessaa dhufte? | J20: Oromo literally 'where did you come from?'. | K20: High | L20: Medium | M20: Draft | N20: Draft | O20: N | P20: N
A21: W020 | B21: S1-U02-L2 | C21: 1 | D21: Introductions | E21: Where are you from? | F21: I am from … | G21: ከ… ነኝ | H21: ke… negn | I21: Ani … irraa dhufe | K21: High | L21: Medium | M21: Draft | N21: Draft | O21: N | P21: N
A22: W021 | B22: S1-U02-L3 | C22: 1 | D22: Introductions | E22: Nice to meet you | F22: welcome | G22: እንኳን ደህና መጡ | H22: inkwan dehna metu | I22: Baga nagaan dhufte | J22: Amharic polite; to a man መጣህ, to a woman መጣሽ. | K22: High | L22: High | M22: Draft | N22: Draft | O22: N | P22: N
A23: W022 | B23: S1-U02-L3 | C23: 1 | D23: Introductions | E23: Nice to meet you | F23: Nice to meet you | G23: ስለተዋወቅን ደስ ብሎኛል | H23: siletewawoqin des bilognal | I23: Si beekuu kootti gammadeera | K23: Medium | L23: Low | M23: Draft | N23: Draft | O23: N | P23: N
A24: W023 | B24: S1-U02-L3 | C24: 1 | D24: Introductions | E24: Nice to meet you | F24: See you later | G24: በኋላ እንገናኝ | H24: behwala inignagn | I24: Booda wal arginaa | K24: Medium | L24: Medium | M24: Draft | N24: Draft | O24: N | P24: N
A25: W024 | B25: S1-U02-L3 | C25: 1 | D25: Introductions | E25: Nice to meet you | F25: friend | G25: ጓደኛ | H25: gwadegna | I25: hiriyaa | K25: High | L25: High | M25: Draft | N25: Draft | O25: N | P25: N
A26: W025 | B26: S1-U03-L1 | C26: 1 | D26: People | E26: I & you | F26: I | G26: እኔ | H26: ine | I26: ani | K26: High | L26: High | M26: Draft | N26: Draft | O26: N | P26: N
A27: W026 | B27: S1-U03-L1 | C27: 1 | D27: People | E27: I & you | F27: you (to a man) | G27: አንተ | H27: ante | I27: ati | J27: Oromo 'ati' is the same for a man and a woman. | K27: High | L27: High | M27: Draft | N27: Draft | O27: N | P27: N
A28: W027 | B28: S1-U03-L1 | C28: 1 | D28: People | E28: I & you | F28: you (to a woman) | G28: አንቺ | H28: anchi | I28: ati | K28: High | L28: High | M28: Draft | N28: Draft | O28: N | P28: N
A29: W028 | B29: S1-U03-L1 | C29: 1 | D29: People | E29: I & you | F29: you (polite) | G29: እርስዎ | H29: irswo | I29: isin | J29: Oromo 'isin' is also 'you (plural)'. | K29: High | L29: High | M29: Draft | N29: Draft | O29: N | P29: N
A30: W029 | B30: S1-U03-L2 | C30: 1 | D30: People | E30: He, she, we, they | F30: he | G30: እሱ | H30: issu | I30: inni | K30: High | L30: High | M30: Draft | N30: Draft | O30: N | P30: N
A31: W030 | B31: S1-U03-L2 | C31: 1 | D31: People | E31: He, she, we, they | F31: she | G31: እሷ | H31: isswa | I31: isheen | K31: High | L31: High | M31: Draft | N31: Draft | O31: N | P31: N
A32: W031 | B32: S1-U03-L2 | C32: 1 | D32: People | E32: He, she, we, they | F32: we | G32: እኛ | H32: igna | I32: nuyi | J32: Oromo also written nu'i. | K32: High | L32: Medium | M32: Draft | N32: Draft | O32: N | P32: N
A33: W032 | B33: S1-U03-L2 | C33: 1 | D33: People | E33: He, she, we, they | F33: they | G33: እነሱ | H33: innesu | I33: isaan | K33: High | L33: High | M33: Draft | N33: Draft | O33: N | P33: N
A34: W033 | B34: S1-U03-L3 | C34: 1 | D34: People | E34: Man, woman, teacher | F34: man | G34: ወንድ | H34: wend | I34: dhiira | K34: High | L34: High | M34: Draft | N34: Draft | O34: N | P34: N
A35: W034 | B35: S1-U03-L3 | C35: 1 | D35: People | E35: Man, woman, teacher | F35: woman | G35: ሴት | H35: set | I35: dubartii | K35: High | L35: High | M35: Draft | N35: Draft | O35: N | P35: N
A36: W035 | B36: S1-U03-L3 | C36: 1 | D36: People | E36: Man, woman, teacher | F36: teacher | G36: አስተማሪ | H36: astemari | I36: barsiisaa | J36: Oromo female teacher: barsiistuu. | K36: High | L36: High | M36: Draft | N36: Draft | O36: N | P36: N
A37: W036 | B37: S1-U03-L3 | C37: 1 | D37: People | E37: Man, woman, teacher | F37: student | G37: ተማሪ | H37: temari | I37: barataa | J37: Oromo female student: barattuu. | K37: High | L37: High | M37: Draft | N37: Draft | O37: N | P37: N
A38: W037 | B38: S1-U04-L1 | C38: 1 | D38: Family | E38: Mother & father | F38: mother | G38: እናት | H38: inat | I38: haadha | J38: Oromo subject form: haati. | K38: High | L38: High | M38: Draft | N38: Draft | O38: N | P38: N
A39: W038 | B39: S1-U04-L1 | C39: 1 | D39: Family | E39: Mother & father | F39: father | G39: አባት | H39: abat | I39: abbaa | K39: High | L39: High | M39: Draft | N39: Draft | O39: N | P39: N
A40: W039 | B40: S1-U04-L1 | C40: 1 | D40: Family | E40: Mother & father | F40: brother | G40: ወንድም | H40: wendim | I40: obboleessa | K40: High | L40: High | M40: Draft | N40: Draft | O40: N | P40: N
...

Sheet Sentences
A1: Sentence ID | B1: Lesson ID | C1: Section | D1: Lesson | E1: English | F1: Amharic (Fidel) | G1: Amharic romanization | H1: Amharic word to blank | I1: Other accepted Amharic | J1: Afaan Oromo | K1: Oromo word to blank | L1: Other accepted Oromo | M1: Notes | N1: Claude confidence: Amharic | O1: Claude confidence: Oromo | P1: Status: Amharic | Q1: Status: Oromo | R1: Audio: Amharic | S1: Audio: Oromo | T1: Reviewer comments
A2: S001 | B2: S1-U01-L1 | C2: 1 | D2: Hello & goodbye | E2: Goodbye, good night | F2: ደህና ይሁኑ፣ ደህና ይደሩ | G2: dehna yihunu, dehna yideru | H2: ይደሩ | J2: Nagaatti, halkan gaarii | K2: halkan | N2: High | O2: Medium | P2: Draft | Q2: Draft | R2: N | S2: N
A3: S002 | B3: S1-U01-L2 | C3: 1 | D3: How are you? | E3: I am fine, and you? | F3: ደህና ነኝ፣ እርስዎስ? | G3: dehna negn, irswos? | H3: ደህና | J3: Nagaa dha, ati hoo? | K3: Nagaa | N3: High | O3: Low | P3: Draft | Q3: Draft | R3: N | S3: N
A4: S003 | B4: S1-U01-L3 | C4: 1 | D4: Thank you & sorry | E4: I am fine, thank you | F4: ደህና ነኝ፣ አመሰግናለሁ | G4: dehna negn, ameseginalehu | H4: አመሰግናለሁ | J4: Nagaa dha, galatoomi | K4: galatoomi | N4: High | O4: Medium | P4: Draft | Q4: Draft | R4: N | S4: N
A5: S004 | B5: S1-U02-L1 | C5: 1 | D5: My name is… | E5: My name is Sara | F5: ስሜ ሳራ ነው | G5: sime Sara new | H5: ስሜ | J5: Maqaan koo Saaraa dha | K5: Maqaan | N5: High | O5: High | P5: Draft | Q5: Draft | R5: N | S5: N
A6: S005 | B6: S1-U02-L2 | C6: 1 | D6: Where are you from? | E6: I am from Ethiopia | F6: ከኢትዮጵያ ነኝ | G6: ke-Ityopya negn | H6: ከኢትዮጵያ | J6: Ani Itoophiyaa irraa dhufe | K6: Itoophiyaa | N6: High | O6: Medium | P6: Draft | Q6: Draft | R6: N | S6: N
A7: S006 | B7: S1-U02-L3 | C7: 1 | D7: Nice to meet you | E7: Welcome, my friend | F7: እንኳን ደህና መጡ ጓደኛዬ | G7: inkwan dehna metu gwadeNNaye | H7: ጓደኛዬ | J7: Baga nagaan dhufte, hiriyaa koo | K7: hiriyaa | N7: High | O7: High | P7: Draft | Q7: Draft | R7: N | S7: N
A8: S007 | B8: S1-U03-L1 | C8: 1 | D8: I & you | E8: I am Sara | F8: እኔ ሳራ ነኝ | G8: ine Sara negn | H8: እኔ | J8: Ani Saaraa dha | K8: Ani | N8: High | O8: High | P8: Draft | Q8: Draft | R8: N | S8: N
A9: S008 | B9: S1-U03-L2 | C9: 1 | D9: He, she, we, they | E9: She is my friend | F9: እሷ ጓደኛዬ ናት | G9: isswa gwadeNNaye nat | H9: እሷ | J9: Isheen hiriyaa koo ti | K9: Isheen | N9: High | O9: Medium | P9: Draft | Q9: Draft | R9: N | S9: N
A10: S009 | B10: S1-U03-L3 | C10: 1 | D10: Man, woman, teacher | E10: He is a teacher | F10: እሱ አስተማሪ ነው | G10: issu astemari new | H10: አስተማሪ | J10: Inni barsiisaa dha | K10: barsiisaa | N10: High | O10: High | P10: Draft | Q10: Draft | R10: N | S10: N
A11: S010 | B11: S1-U04-L1 | C11: 1 | D11: Mother & father | E11: I have a brother | F11: ወንድም አለኝ | G11: wendim alegn | H11: ወንድም | J11: Obboleessa qaba | K11: Obboleessa | N11: High | O11: High | P11: Draft | Q11: Draft | R11: N | S11: N
A12: S011 | B12: S1-U04-L2 | C12: 1 | D12: Husband, wife & child | E12: I have a child | F12: ልጅ አለኝ | G12: lij alegn | H12: ልጅ | J12: Mucaa qaba | K12: Mucaa | N12: High | O12: High | P12: Draft | Q12: Draft | R12: N | S12: N
A13: S012 | B13: S1-U04-L3 | C13: 1 | D13: My family | E13: My mother is a teacher | F13: እናቴ አስተማሪ ናት | G13: inate astemari nat | H13: እናቴ | J13: Haati koo barsiistuu dha | K13: barsiistuu | M13: Oromo: haadha → haati (subject), barsiisaa → barsiistuu (female). | N13: High | O13: Medium | P13: Draft | Q13: Draft | R13: N | S13: N
A14: S013 | B14: S1-U05-L1 | C14: 1 | D14: One to five | E14: I have two brothers | F14: ሁለት ወንድሞች አሉኝ | G14: hulet wendimoch allugn | H14: ሁለት | J14: Obboleeyyan lama qaba | K14: lama | M14: Oromo plural of obboleessa needs checking. | N14: High | O14: Low | P14: Draft | Q14: Draft | R14: N | S14: N
A15: S014 | B15: S1-U05-L2 | C15: 1 | D15: Six to ten | E15: Ten children | F15: አስር ልጆች | G15: asir lijoch | H15: አስር | J15: Ijoollee kudhan | K15: kudhan | M15: Oromo puts the number after the noun. | N15: High | O15: High | P15: Draft | Q15: Draft | R15: N | S15: N
A16: S015 | B16: S1-U05-L3 | C16: 1 | D16: How many? | E16: How many children do you have? | F16: ስንት ልጆች አሉዎት? | G16: sint lijoch alluwot? | H16: ስንት | J16: Ijoollee meeqa qabda? | K16: meeqa | N16: High | O16: High | P16: Draft | Q16: Draft | R16: N | S16: N
A17: S016 | B17: S1-U06-L1 | C17: 1 | D17: Coffee, tea & water | E17: Coffee, please | F17: ቡና እባክዎ | G17: bunna ibakwo | H17: ቡና | J17: Buna maaloo | K17: Buna | N17: High | O17: High | P17: Draft | Q17: Draft | R17: N | S17: N
A18: S017 | B18: S1-U06-L2 | C18: 1 | D18: Bread & food | E18: I want bread | F18: ዳቦ እፈልጋለሁ | G18: dabo ifeligalehu | H18: ዳቦ | J18: Daabboo nan barbaada | K18: Daabboo | N18: High | O18: High | P18: Draft | Q18: Draft | R18: N | S18: N
A19: S018 | B19: S1-U06-L3 | C19: 1 | D19: I want, I drink | E19: I drink coffee | F19: ቡና እጠጣለሁ | G19: bunna iteTalehu | H19: እጠጣለሁ | J19: Buna nan dhuga | K19: dhuga | N19: High | O19: High | P19: Draft | Q19: Draft | R19: N | S19: N
A20: S019 | B20: S1-U07-L1 | C20: 1 | D20: Ordering | E20: Please give me tea | F20: እባክዎ ሻይ ይስጡኝ | G20: ibakwo shay yisTugn | H20: ሻይ | J20: Maaloo shaayii naaf kenni | K20: shaayii | N20: High | O20: High | P20: Draft | Q20: Draft | R20: N | S20: N
A21: S020 | B21: S1-U07-L2 | C21: 1 | D21: How much is it? | E21: How much is the coffee? | F21: ቡናው ስንት ነው? | G21: bunnaw sint new? | H21: ስንት | J21: Gatiin bunaa meeqa? | K21: meeqa | N21: High | O21: Medium | P21: Draft | Q21: Draft | R21: N | S21: N
A22: S021 | B22: S1-U07-L3 | C22: 1 | D22: Hot & tasty | E22: The coffee is hot | F22: ቡናው ትኩስ ነው | G22: bunnaw tikus new | H22: ትኩስ | J22: Bunni ho'aa dha | K22: ho'aa | M22: Oromo: buna → bunni (subject). | N22: High | O22: Medium | P22: Draft | Q22: Draft | R22: N | S22: N
A23: S022 | B23: S1-U08-L1 | C23: 1 | D23: Today & tomorrow | E23: I want coffee now | F23: አሁን ቡና እፈልጋለሁ | G23: ahun bunna ifeligalehu | H23: አሁን | J23: Amma buna nan barbaada | K23: Amma | N23: High | O23: High | P23: Draft | Q23: Draft | R23: N | S23: N
A24: S023 | B24: S1-U08-L2 | C24: 1 | D24: Monday to Thursday | E24: Today is Monday | F24: ዛሬ ሰኞ ነው | G24: zare segno new | H24: ሰኞ | J24: Har'a Wiixata dha | K24: Wiixata | N24: High | O24: High | P24: Draft | Q24: Draft | R24: N | S24: N
A25: S024 | B25: S1-U08-L3 | C25: 1 | D25: Friday to Sunday | E25: Tomorrow is Sunday | F25: ነገ እሁድ ነው | G25: nege ihud new | H25: እሁድ | J25: Boru Dilbata dha | K25: Dilbata | N25: High | O25: High | P25: Draft | Q25: Draft | R25: N | S25: N
A26: S025 | B26: S1-U09-L1 | C26: 1 | D26: Places | E26: I go to the market | F26: ወደ ገበያ እሄዳለሁ | G26: wede gebeya ihedalehu | H26: ገበያ | J26: Gara gabaa nan deema | K26: gabaa | N26: High | O26: High | P26: Draft | Q26: Draft | R26: N | S26: N
A27: S026 | B27: S1-U09-L2 | C27: 1 | D27: Where is it? | E27: Where is the school? | F27: ትምህርት ቤቱ የት ነው? | G27: timhirt betu yet new? | H27: የት | J27: Manni barumsaa eessa jira? | K27: eessa | N27: High | O27: High | P27: Draft | Q27: Draft | R27: N | S27: N
A28: S027 | B28: S1-U09-L3 | C28: 1 | D28: Directions | E28: The market is far | F28: ገበያው ሩቅ ነው | G28: gebeyaw ruq new | H28: ሩቅ | J28: Gabaan fagoo dha | K28: fagoo | N28: High | O28: Medium | P28: Draft | Q28: Draft | R28: N | S28: N
A29: S028 | B29: S1-U10-L1 | C29: 1 | D29: Colours | E29: The coffee is black | F29: ቡናው ጥቁር ነው | G29: bunnaw Tiqur new | H29: ጥቁር | J29: Bunni gurraacha dha | K29: gurraacha | N29: High | O29: Medium | P29: Draft | Q29: Draft | R29: N | S29: N
A30: S029 | B30: S1-U10-L2 | C30: 1 | D30: Big & small | E30: My house is small | F30: ቤቴ ትንሽ ነው | G30: bete tinnish new | H30: ትንሽ | J30: Manni koo xiqqaa dha | K30: xiqqaa | N30: High | O30: High | P30: Draft | Q30: Draft | R30: N | S30: N
A31: S030 | B31: S1-U10-L3 | C31: 1 | D31: Good & beautiful | E31: Ethiopia is very beautiful | F31: ኢትዮጵያ በጣም ቆንጆ ናት | G31: Ityopya beTam qonjo nat | H31: ቆንጆ | J31: Itoophiyaan baay'ee bareedduu dha | K31: bareedduu | M31: Countries are feminine in both languages. | N31: High | O31: Medium | P31: Draft | Q31: Draft | R31: N | S31: N
A32: S031 | B32: S2-U11-L1 | C32: 2 | D32: Eleven to twenty | E32: I have twenty birr | P32: To do | Q32: To do | R32: N | S32: N
A33: S032 | B33: S2-U11-L2 | C33: 2 | D33: Tens & hundreds | E33: One hundred birr | P33: To do | Q33: To do | R33: N | S33: N
A34: S033 | B34: S2-U11-L3 | C34: 2 | D34: Paying | E34: This is very expensive | P34: To do | Q34: To do | R34: N | S34: N
A35: S034 | B35: S2-U12-L1 | C35: 2 | D35: Parts of the day | E35: Good evening | P35: To do | Q35: To do | R35: N | S35: N
A36: S035 | B36: S2-U12-L2 | C36: 2 | D36: What time is it? | E36: What time is it? | P36: To do | Q36: To do | R36: N | S36: N
A37: S036 | B37: S2-U12-L3 | C37: 2 | D37: Early & late | E37: I am late | P37: To do | Q37: To do | R37: N | S37: N
A38: S037 | B38: S2-U13-L1 | C38: 2 | D38: Morning | E38: I wake up early | P38: To do | Q38: To do | R38: N | S38: N
A39: S038 | B39: S2-U13-L2 | C39: 2 | D39: Day | E39: I work every day | P39: To do | Q39: To do | R39: N | S39: N
A40: S039 | B40: S2-U13-L3 | C40: 2 | D40: How often | E40: I sometimes cook | P40: To do | Q40: To do | R40: N | S40: N
...

Sheet Progress
A1: Section | B1: Words | C1: Amharic filled | D1: Amharic reviewed | E1: Oromo filled | F1: Oromo reviewed | G1: Amharic audio | H1: Oromo audio | I1: Sentences | J1: Amharic sentences reviewed | K1: Oromo sentences reviewed
A2: 1 | B2: =COUNTIF(Words!$C$2:$C$269,A2) | C2: =COUNTIFS(Words!$C$2:$C$269,A2,Words!$G$2:$G$269,"?*") | D2: =COUNTIFS(Words!$C$2:$C$269,A2,Words!$M$2:$M$269,"Reviewed") | E2: =COUNTIFS(Words!$C$2:$C$269,A2,Words!$I$2:$I$269,"?*") | F2: =COUNTIFS(Words!$C$2:$C$269,A2,Words!$N$2:$N$269,"Reviewed") | G2: =COUNTIFS(Words!$C$2:$C$269,A2,Words!$O$2:$O$269,"Y") | H2: =COUNTIFS(Words!$C$2:$C$269,A2,Words!$P$2:$P$269,"Y") | I2: =COUNTIF(Sentences!$C$2:$C$67,A2) | J2: =COUNTIFS(Sentences!$C$2:$C$67,A2,Sentences!$P$2:$P$67,"Reviewed") | K2: =COUNTIFS(Sentences!$C$2:$C$67,A2,Sentences!$Q$2:$Q$67,"Reviewed")
A3: 2 | B3: =COUNTIF(Words!$C$2:$C$269,A3) | C3: =COUNTIFS(Words!$C$2:$C$269,A3,Words!$G$2:$G$269,"?*") | D3: =COUNTIFS(Words!$C$2:$C$269,A3,Words!$M$2:$M$269,"Reviewed") | E3: =COUNTIFS(Words!$C$2:$C$269,A3,Words!$I$2:$I$269,"?*") | F3: =COUNTIFS(Words!$C$2:$C$269,A3,Words!$N$2:$N$269,"Reviewed") | G3: =COUNTIFS(Words!$C$2:$C$269,A3,Words!$O$2:$O$269,"Y") | H3: =COUNTIFS(Words!$C$2:$C$269,A3,Words!$P$2:$P$269,"Y") | I3: =COUNTIF(Sentences!$C$2:$C$67,A3) | J3: =COUNTIFS(Sentences!$C$2:$C$67,A3,Sentences!$P$2:$P$67,"Reviewed") | K3: =COUNTIFS(Sentences!$C$2:$C$67,A3,Sentences!$Q$2:$Q$67,"Reviewed")
A4: Total | B4: =SUM(B2:B3) | C4: =SUM(C2:C3) | D4: =SUM(D2:D3) | E4: =SUM(E2:E3) | F4: =SUM(F2:F3) | G4: =SUM(G2:G3) | H4: =SUM(H2:H3) | I4: =SUM(I2:I3) | ... K4: =SUM(K2:K3)
A6: Counts update from the Words and Sentences tabs; 'filled' means the cell is not empty.

Sheet Sources
A1: Source | B1: Language | C1: Licence | D1: Use in the app? | E1: How to use it | F1: Link
A2: FSI Amharic Basic Course | B2: Amharic | C2: Public domain | D2: Yes | E2: Grammar order and dialogues; modernise old vocabulary. | F2: https://archive.org/details/AmharicBasicCourse
A3: Peace Corps Amharic manual | B3: Amharic | C3: Public domain | D3: Yes | E3: Practical topics in a useful order. No audio. | F3: https://www.livelingua.com/course/peace-corps/Amharic_Peace_Corps_Language_Manual
A4: Peace Corps Oromo for Beginners | B4: Afaan Oromo | C4: Public domain | D4: Yes | E4: Greetings, pronouns, numbers, food, commands. | F4: https://www.livelingua.com/peace-corps/Oromo/Peace%20Corps%20Oromo%20for%20Beginners.pdf
A5: Tatoeba | B5: Both | C5: CC BY (credit needed) | D5: Yes, with credit | E5: Example sentences with translations. | F5: https://tatoeba.org/en/downloads
A6: Common Voice Amharic | B6: Amharic | C6: CC0 | D6: Yes | E6: Recorded sentences (about 2,200). | F6: https://mozilladatacollective.com/datasets/cmn29lq6f0164o10748yd3o7w
A7: EthioMT | B7: Both | C7: CC BY 4.0 | D7: Reference | E7: Mostly Bible text: use for word frequency, not lesson text. | F7: https://arxiv.org/abs/2403.19365
A8: CEFR level descriptions | B8: - | C8: Council of Europe | D8: Reference | E8: Can-do goals for each level. | F8: https://www.coe.int/en/web/common-european-framework-reference-languages/level-descriptions
A9: Duolingo: how courses are made | B9: - | C9: Blog | D9: Reference | E9: Curriculum design method. | F9: https://blog.duolingo.com/the-nuts-and-bolts-of-course-creation-at-duolingo/
A10: Scribd / dirzon PDFs, Udemy, school textbooks | B10: Both | C10: Copyrighted | D10: No | E10: Ideas for topics only; do not copy sentences or audio.
